<?xml version="1.0"?>
<!-- This URDF was automatically created by SolidWorks to URDF Exporter! Originally created by Stephen Brawner (brawner@gmail.com) 
     Commit Version: 1.6.0-4-g7f85cfe  Build Version: 1.6.7995.38578
     For more information, please see http://wiki.ros.org/sw_urdf_exporter -->
<robot
  name="mobilearm" xmlns:xacro="http://ros.org/wiki/xacro">

<!-- # Add this before base link -->
  <link name="dummy_link"></link>

  <link
    name="base_link">
    <inertial>
      <origin
        xyz="-0.045448 0.00058284 0.17779"
        rpy="0 0 0" />
      <mass
        value="34.758" />
      <inertia
        ixx="0.62775"
        ixy="4.0881E-05"
        ixz="0.11977"
        iyy="0.78435"
        iyz="-1.5708E-05"
        izz="0.96649" />
    </inertial>
    <visual>
      <origin
        xyz="0 0 0"
        rpy="0 0 0" />
      <geometry>
        <mesh
          filename="package://mobilearm/meshes/base_link.STL" />
      </geometry>
      <material
        name="">
        <color
          rgba="0.79216 0.81961 0.93333 1" />
      </material>
    </visual>
    <collision>
      <origin
        xyz="0 0 0"
        rpy="0 0 0" />
      <geometry>
        <mesh
          filename="package://mobilearm/meshes/base_link.STL" />
      </geometry>
    </collision>
  </link>

<!-- # Add this after base link -->
  <joint name="dummy_joint" type="fixed">
      <origin rpy="0 0 0" xyz="0 0 0" />
      <parent link="dummy_link"/>
      <child link="base_link"/>
  </joint>

  <link
    name="fl_wheel_link">
    <inertial>
      <origin
        xyz="-0.027181 -4.1417E-16 -1.3184E-16"
        rpy="0 0 0" />
      <mass
        value="2.632" />
      <inertia
        ixx="0.04377"
        ixy="-2.8081E-17"
        ixz="-1.1886E-17"
        iyy="0.023024"
        iyz="-1.1907E-18"
        izz="0.023024" />
    </inertial>
    <visual>
      <origin
        xyz="0 0 0"
        rpy="0 0 0" />
      <geometry>
        <mesh
          filename="package://mobilearm/meshes/fl_wheel_link.STL" />
      </geometry>
      <material
        name="">
        <color
          rgba="0.79216 0.81961 0.93333 1" />
      </material>
    </visual>
    <collision>
      <origin
        xyz="0 0 0"
        rpy="0 0 0" />
      <geometry>
        <mesh
          filename="package://mobilearm/meshes/fl_wheel_link.STL" />
      </geometry>
    </collision>
  </link>
  <joint
    name="fl_wheel_joint"
    type="continuous">
    <origin
      xyz="0.0855424170995859 0.172671545820042 0.0887956872982283"
      rpy="1.5707963267949 0 -1.5707963267949" />
    <parent
      link="base_link" />
    <child
      link="fl_wheel_link" />
    <axis
      xyz="-1 0 0" />
  </joint>
  <link
    name="fr_wheel_link">
    <inertial>
      <origin
        xyz="-2.4286E-16 3.9682E-16 0.027181"
        rpy="0 0 0" />
      <mass
        value="2.632" />
      <inertia
        ixx="0.023024"
        ixy="8.2369E-17"
        ixz="1.2563E-17"
        iyy="0.023024"
        iyz="-2.6693E-17"
        izz="0.04377" />
    </inertial>
    <visual>
      <origin
        xyz="0 0 0"
        rpy="0 0 0" />
      <geometry>
        <mesh
          filename="package://mobilearm/meshes/fr_wheel_link.STL" />
      </geometry>
      <material
        name="">
        <color
          rgba="0.79216 0.81961 0.93333 1" />
      </material>
    </visual>
    <collision>
      <origin
        xyz="0 0 0"
        rpy="0 0 0" />
      <geometry>
        <mesh
          filename="package://mobilearm/meshes/fr_wheel_link.STL" />
      </geometry>
    </collision>
  </link>
  <joint
    name="fr_wheel_joint"
    type="continuous">
    <origin
      xyz="0.0855424170995859 -0.171498454179958 0.0887956872982283"
      rpy="1.5707963267949 0 0" />
    <parent
      link="base_link" />
    <child
      link="fr_wheel_link" />
    <axis
      xyz="0 0 1" />
  </joint>
  <link
    name="caster_steering_link">
    <inertial>
      <origin
        xyz="-0.015554 -0.050212 -0.021872"
        rpy="0 0 0" />
      <mass
        value="0.1049" />
      <inertia
        ixx="0.00024545"
        ixy="-5.4866E-05"
        ixz="-1.1598E-05"
        iyy="0.00010985"
        iyz="-7.7153E-05"
        izz="0.00023739" />
    </inertial>
    <visual>
      <origin
        xyz="0 0 0"
        rpy="0 0 0" />
      <geometry>
        <mesh
          filename="package://mobilearm/meshes/caster_steering_link.STL" />
      </geometry>
      <material
        name="">
        <color
          rgba="0.79216 0.81961 0.93333 1" />
      </material>
    </visual>
    <collision>
      <origin
        xyz="0 0 0"
        rpy="0 0 0" />
      <geometry>
        <mesh
          filename="package://mobilearm/meshes/caster_steering_link.STL" />
      </geometry>
    </collision>
  </link>
  <joint
    name="caster_steering_joint"
    type="continuous">
    <origin
      xyz="-0.204564404538145 0.000586545820041112 0.092302154967211"
      rpy="1.5707963267949 0 0" />
    <parent
      link="base_link" />
    <child
      link="caster_steering_link" />
    <axis
      xyz="0 1 0" />
  </joint>
  <link
    name="caster_wheel_link">
    <inertial>
      <origin
        xyz="2.22044604925031E-16 6.93889390390723E-17 2.46330733588707E-16"
        rpy="0 0 0" />
      <mass
        value="0.342625566923817" />
      <inertia
        ixx="0.000635022853102609"
        ixy="-1.22660123963122E-19"
        ixz="-0.000166314971068249"
        iyy="0.000401151285704393"
        iyz="1.37432861193586E-19"
        izz="0.000519424190397995" />
    </inertial>
    <visual>
      <origin
        xyz="0 0 0"
        rpy="0 0 0" />
      <geometry>
        <mesh
          filename="package://mobilearm/meshes/caster_wheel_link.STL" />
      </geometry>
      <material
        name="">
        <color
          rgba="0.792156862745098 0.819607843137255 0.933333333333333 1" />
      </material>
    </visual>
    <collision>
      <origin
        xyz="0 0 0"
        rpy="0 0 0" />
      <geometry>
        <mesh
          filename="package://mobilearm/meshes/caster_wheel_link.STL" />
      </geometry>
    </collision>
  </link>
  <joint
    name="caster_wheel_joint"
    type="continuous">
    <origin
      xyz="-0.0281460805399568 -0.0920750000000002 -0.039578926236865"
      rpy="0 0 0" />
    <parent
      link="caster_steering_link" />
    <child
      link="caster_wheel_link" />
    <axis
      xyz="-0.814944954891572 0 0.579538368442309" />
  </joint>
  <link
    name="arm_base_link">
    <inertial>
      <origin
        xyz="-2.57901941051741E-05 0.0132552322045653 2.20102892162233E-09"
        rpy="0 0 0" />
      <mass
        value="0.306924619891199" />
      <inertia
        ixx="0.000564283838712626"
        ixy="4.77513581324576E-07"
        ixz="-2.64534906819143E-10"
        iyy="0.000624476724758926"
        iyz="-2.20937960001254E-10"
        izz="0.000464836817681594" />
    </inertial>
    <visual>
      <origin
        xyz="0 0 0"
        rpy="0 0 0" />
      <geometry>
        <mesh
          filename="package://mobilearm/meshes/arm_base_link.STL" />
      </geometry>
      <material
        name="">
        <color
          rgba="0.792156862745098 0.819607843137255 0.933333333333333 1" />
      </material>
    </visual>
    <collision>
      <origin
        xyz="0 0 0"
        rpy="0 0 0" />
      <geometry>
        <mesh
          filename="package://mobilearm/meshes/arm_base_link.STL" />
      </geometry>
    </collision>
  </link>
  <joint
    name="arm_base_joint"
    type="revolute">
    <origin
      xyz="-0.116265372914888 0.000586545820041961 0.31469370128076"
      rpy="1.5707963267949 0 0" />
    <parent
      link="base_link" />
    <child
      link="arm_base_link" />
    <axis
      xyz="0 1 0" />
    <limit
      lower="-10.42"
      upper="10.42"
      effort="5"
      velocity="5" />
  </joint>
  <link
    name="arm_shoulder_link">
    <inertial>
      <origin
        xyz="-0.107585980315301 0.0127027238235902 0.0393688564782083"
        rpy="0 0 0" />
      <mass
        value="0.425781076841082" />
      <inertia
        ixx="0.000723434497409713"
        ixy="0.000130954228938278"
        ixz="-2.07757094423152E-08"
        iyy="0.00485977948124"
        iyz="2.00545470743252E-09"
        izz="0.00486634901098901" />
    </inertial>
    <visual>
      <origin
        xyz="0 0 0"
        rpy="0 0 0" />
      <geometry>
        <mesh
          filename="package://mobilearm/meshes/arm_shoulder_link.STL" />
      </geometry>
      <material
        name="">
        <color
          rgba="0.792156862745098 0.819607843137255 0.933333333333333 1" />
      </material>
    </visual>
    <collision>
      <origin
        xyz="0 0 0"
        rpy="0 0 0" />
      <geometry>
        <mesh
          filename="package://mobilearm/meshes/arm_shoulder_link.STL" />
      </geometry>
    </collision>
  </link>
  <joint
    name="arm_shoulder_joint"
    type="revolute">
    <origin
      xyz="0.00127 0.07366 -0.03937"
      rpy="0 0 0" />
    <parent
      link="arm_base_link" />
    <child
      link="arm_shoulder_link" />
    <axis
      xyz="0 0 -1" />
    <limit
      lower="-10.42"
      upper="10.42"
      effort="5"
      velocity="5" />
  </joint>
  <link
    name="arm_elbow_link">
    <inertial>
      <origin
        xyz="-0.0700938290895637 -0.00663021674985753 0.0330262353866725"
        rpy="0 0 0" />
      <mass
        value="0.216322084241014" />
      <inertia
        ixx="0.000243507176165999"
        ixy="-2.56629187680897E-05"
        ixz="4.23390520334268E-08"
        iyy="0.00127534950503716"
        iyz="-3.13443560210142E-09"
        izz="0.00126560879258571" />
    </inertial>
    <visual>
      <origin
        xyz="0 0 0"
        rpy="0 0 0" />
      <geometry>
        <mesh
          filename="package://mobilearm/meshes/arm_elbow_link.STL" />
      </geometry>
      <material
        name="">
        <color
          rgba="0.792156862745098 0.819607843137255 0.933333333333333 1" />
      </material>
    </visual>
    <collision>
      <origin
        xyz="0 0 0"
        rpy="0 0 0" />
      <geometry>
        <mesh
          filename="package://mobilearm/meshes/arm_elbow_link.STL" />
      </geometry>
    </collision>
  </link>
  <joint
    name="arm_elbow_joint"
    type="revolute">
    <origin
      xyz="-0.3048 0 0.00635000000000006"
      rpy="0 0 0" />
    <parent
      link="arm_shoulder_link" />
    <child
      link="arm_elbow_link" />
    <axis
      xyz="0 0 -1" />
    <limit
      lower="-10.42"
      upper="10.42"
      effort="5"
      velocity="5" />
  </joint>
  <link
    name="arm_wrist_link">
    <inertial>
      <origin
        xyz="-0.122291575367972 -0.0282391014559717 0.0279400100137721"
        rpy="0 0 0" />
      <mass
        value="0.670549172003677" />
      <inertia
        ixx="0.00365726702375741"
        ixy="-0.00132282579907981"
        ixz="-1.53785293492331E-10"
        iyy="0.00897433588406445"
        iyz="-3.97825385094693E-10"
        izz="0.0074401806695064" />
    </inertial>
    <visual>
      <origin
        xyz="0 0 0"
        rpy="0 0 0" />
      <geometry>
        <mesh
          filename="package://mobilearm/meshes/arm_wrist_link.STL" />
      </geometry>
      <material
        name="">
        <color
          rgba="0.792156862745098 0.819607843137255 0.933333333333333 1" />
      </material>
    </visual>
    <collision>
      <origin
        xyz="0 0 0"
        rpy="0 0 0" />
      <geometry>
        <mesh
          filename="package://mobilearm/meshes/arm_wrist_link.STL" />
      </geometry>
    </collision>
  </link>
  <joint
    name="arm_wrist_joint"
    type="revolute">
    <origin
      xyz="-0.203221215421091 0 0.00508000000000013"
      rpy="0 0 0" />
    <parent
      link="arm_elbow_link" />
    <child
      link="arm_wrist_link" />
    <axis
      xyz="0 0 -1" />
    <limit
      lower="0"
      upper="0"
      effort="5"
      velocity="5" />
  </joint>

  <ros2_control name="GazeboSystem" type="system">
    <hardware>
        <plugin>gazebo_ros2_control/GazeboSystem</plugin>
    </hardware>

  <!-- # Velocity Controllers -->
  <joint name="fl_wheel_joint">
      <command_interface name="velocity">
          <param name="min">-5.0</param>
          <param name="max">5.0</param>
      </command_interface>
      <state_interface name="position"/>
      <state_interface name="velocity"/>
  </joint>

  <joint name="fr_wheel_joint">
      <command_interface name="velocity">
          <param name="min">-5.0</param>
          <param name="max">5.0</param>
      </command_interface>
      <state_interface name="position"/>
      <state_interface name="velocity"/>
  </joint>

 <joint name="arm_base_joint">
      <command_interface name="velocity">
          <param name="min">-5.0</param>
          <param name="max">5.0</param>
      </command_interface>
      <state_interface name="position"/>
      <state_interface name="velocity"/>
  </joint>

  <joint name="arm_shoulder_joint">
      <command_interface name="velocity">
          <param name="min">-5.0</param>
          <param name="max">5.0</param>
      </command_interface>
      <state_interface name="position"/>
      <state_interface name="velocity"/>
  </joint>

 <joint name="arm_elbow_joint">
      <command_interface name="velocity">
          <param name="min">-5.0</param>
          <param name="max">5.0</param>
      </command_interface>
      <state_interface name="position"/>
      <state_interface name="velocity"/>
  </joint>

  <joint name="arm_wrist_joint">
      <command_interface name="velocity">
          <param name="min">-5.0</param>
          <param name="max">5.0</param>
      </command_interface>
      <state_interface name="position"/>
      <state_interface name="velocity"/>
  </joint>

 <joint name="caster_steering_joint">
      <command_interface name="velocity">
          <param name="min">-5.0</param>
          <param name="max">5.0</param>
      </command_interface>
      <state_interface name="position"/>
      <state_interface name="velocity"/>
  </joint>

  <joint name="caster_wheel_joint">
      <command_interface name="velocity">
          <param name="min">-5.0</param>
          <param name="max">5.0</param>
      </command_interface>
      <state_interface name="position"/>
      <state_interface name="velocity"/>
  </joint>

  <!-- # Position Controller -->
  <joint name="arm_base_joint">
      <command_interface name="position">
          <param name="min">-10.42</param>
          <param name="max">10.42</param>
      </command_interface>
      <state_interface name="position"/>
      <state_interface name="velocity"/>
  </joint>

  <joint name="arm_shoulder_joint">
      <command_interface name="position">
          <param name="min">-10.42</param>
          <param name="max">10.42</param>
      </command_interface>
      <state_interface name="position"/>
      <state_interface name="velocity"/>
  </joint>

  <joint name="arm_elbow_joint">
      <command_interface name="position">
          <param name="min">-10.42</param>
          <param name="max">10.42</param>
      </command_interface>
      <state_interface name="position"/>
      <state_interface name="velocity"/>
  </joint>

  <joint name="arm_wrist_joint">
      <command_interface name="position">
          <param name="min">-10.42</param>
          <param name="max">10.42</param>
      </command_interface>
      <state_interface name="position"/>
      <state_interface name="velocity"/>
  </joint>

  </ros2_control>

<gazebo>
  <plugin filename="libgazebo_ros2_control.so" name="gazebo_ros2_control">
    <parameters>$(find mobilearm)/config/control.yaml</parameters>
  </plugin>
</gazebo>

<gazebo reference="base_link">
  <sensor name="lidar" type="ray">
    <pose>0.0 0.0 0.0 0.0 0.0 0.0</pose>
    <always_on>true</always_on>
    <visualize>true</visualize>
    <update_rate>5</update_rate>
    <ray>
      <scan>
        <horizontal>
          <samples>360</samples>
          <resolution>1.00000</resolution>
          <min_angle>0.000000</min_angle>
          <max_angle>6.280000</max_angle>
        </horizontal>
      </scan>
      <range>
        <min>0.120000</min>
        <max>3.5</max>
        <resolution>0.015000</resolution>
      </range>
      <noise>
        <type>gaussian</type>
        <mean>0.0</mean>
        <stddev>0.01</stddev>
      </noise>
    </ray>
    <plugin name="scan" filename="libgazebo_ros_ray_sensor.so">
      <ros>
        <remapping>~/out:=scan</remapping>
      </ros>
      <output_type>sensor_msgs/LaserScan</output_type>
      <frame_name>lidar_link</frame_name>
    </plugin>
  </sensor>
  </gazebo>

</robot>